[2024-10-20 12:59:41 UTC] Step clean_df has started.

[2024-10-20 12:59:41 UTC] Error in data divison:'Performance Index'

[2024-10-20 12:59:41 UTC] Error in handling data:'Performance Index'

[2024-10-20 12:59:41 UTC] Error in cleaning and splitting data: 'Performance Index'

[2024-10-20 12:59:41 UTC] Failed to run step clean_df after 1 retries. Exiting.

[2024-10-20 12:59:41 UTC] 'Performance Index'
Traceback (most recent call last):
  File "/mnt/c/Users/risha/Desktop/retail-prize-optimization-MLOps/venv/lib/python3.10/site-packages/pandas/core/indexes/base.py", line 3805, in get_loc
    return self._engine.get_loc(casted_key)
  File "index.pyx", line 167, in pandas._libs.index.IndexEngine.get_loc
  File "index.pyx", line 196, in pandas._libs.index.IndexEngine.get_loc
  File "pandas/_libs/hashtable_class_helper.pxi", line 7081, in pandas._libs.hashtable.PyObjectHashTable.get_item
  File "pandas/_libs/hashtable_class_helper.pxi", line 7089, in pandas._libs.hashtable.PyObjectHashTable.get_item
KeyError: 'Performance Index'

The above exception was the direct cause of the following exception:

Traceback (most recent call last):
  File "/mnt/c/Users/risha/Desktop/retail-prize-optimization-MLOps/venv/lib/python3.10/site-packages/zenml/orchestrators/step_launcher.py", line 292, in launch
    self._run_step(
  File "/mnt/c/Users/risha/Desktop/retail-prize-optimization-MLOps/venv/lib/python3.10/site-packages/zenml/orchestrators/step_launcher.py", line 499, in _run_step
    self._run_step_without_step_operator(
  File "/mnt/c/Users/risha/Desktop/retail-prize-optimization-MLOps/venv/lib/python3.10/site-packages/zenml/orchestrators/step_launcher.py", line 583, in _run_step_without_step_operator
    runner.run(
  File "/mnt/c/Users/risha/Desktop/retail-prize-optimization-MLOps/venv/lib/python3.10/site-packages/zenml/orchestrators/step_runner.py", line 198, in run
    return_values = step_instance.call_entrypoint(
  File "/mnt/c/Users/risha/Desktop/retail-prize-optimization-MLOps/venv/lib/python3.10/site-packages/zenml/steps/base_step.py", line 692, in call_entrypoint
    return self.entrypoint(**validated_args)
  File "/mnt/c/Users/risha/Desktop/retail-prize-optimization-MLOps/steps/clean_data.py", line 34, in clean_df
    raise e
  File "/mnt/c/Users/risha/Desktop/retail-prize-optimization-MLOps/steps/clean_data.py", line 25, in clean_df
    X_train, X_test, y_train, y_test = data_cleaning.handle_data()
  File "/mnt/c/Users/risha/Desktop/retail-prize-optimization-MLOps/src/data_cleaning.py", line 48, in handle_data
    raise e
  File "/mnt/c/Users/risha/Desktop/retail-prize-optimization-MLOps/src/data_cleaning.py", line 45, in handle_data
    return self.strategy.handle_data(self.data)
  File "/mnt/c/Users/risha/Desktop/retail-prize-optimization-MLOps/src/data_cleaning.py", line 34, in handle_data
    raise e
  File "/mnt/c/Users/risha/Desktop/retail-prize-optimization-MLOps/src/data_cleaning.py", line 29, in handle_data
    y=data["Performance Index"]
  File "/mnt/c/Users/risha/Desktop/retail-prize-optimization-MLOps/venv/lib/python3.10/site-packages/pandas/core/series.py", line 1121, in __getitem__
    return self._get_value(key)
  File "/mnt/c/Users/risha/Desktop/retail-prize-optimization-MLOps/venv/lib/python3.10/site-packages/pandas/core/series.py", line 1237, in _get_value
    loc = self.index.get_loc(label)
  File "/mnt/c/Users/risha/Desktop/retail-prize-optimization-MLOps/venv/lib/python3.10/site-packages/pandas/core/indexes/base.py", line 3812, in get_loc
    raise KeyError(key) from err
KeyError: 'Performance Index'

