[2024-10-20 13:24:23 UTC] Step clean_df has started.

[2024-10-20 13:24:23 UTC] Error in data divison:"['Performance Index'] not found in axis"

[2024-10-20 13:24:23 UTC] Error in handling data:"['Performance Index'] not found in axis"

[2024-10-20 13:24:23 UTC] Error in cleaning and splitting data: "['Performance Index'] not found in axis"

[2024-10-20 13:24:23 UTC] Failed to run step clean_df after 1 retries. Exiting.

[2024-10-20 13:24:23 UTC] "['Performance Index'] not found in axis"
Traceback (most recent call last):
  File "/mnt/c/Users/risha/Desktop/retail-prize-optimization-MLOps/venv/lib/python3.10/site-packages/zenml/orchestrators/step_launcher.py", line 292, in launch
    self._run_step(
  File "/mnt/c/Users/risha/Desktop/retail-prize-optimization-MLOps/venv/lib/python3.10/site-packages/zenml/orchestrators/step_launcher.py", line 499, in _run_step
    self._run_step_without_step_operator(
  File "/mnt/c/Users/risha/Desktop/retail-prize-optimization-MLOps/venv/lib/python3.10/site-packages/zenml/orchestrators/step_launcher.py", line 583, in _run_step_without_step_operator
    runner.run(
  File "/mnt/c/Users/risha/Desktop/retail-prize-optimization-MLOps/venv/lib/python3.10/site-packages/zenml/orchestrators/step_runner.py", line 198, in run
    return_values = step_instance.call_entrypoint(
  File "/mnt/c/Users/risha/Desktop/retail-prize-optimization-MLOps/venv/lib/python3.10/site-packages/zenml/steps/base_step.py", line 692, in call_entrypoint
    return self.entrypoint(**validated_args)
  File "/mnt/c/Users/risha/Desktop/retail-prize-optimization-MLOps/steps/clean_data.py", line 34, in clean_df
    raise e
  File "/mnt/c/Users/risha/Desktop/retail-prize-optimization-MLOps/steps/clean_data.py", line 25, in clean_df
    X_train, X_test, y_train, y_test = data_cleaning.handle_data()
  File "/mnt/c/Users/risha/Desktop/retail-prize-optimization-MLOps/src/data_cleaning.py", line 51, in handle_data
    raise e
  File "/mnt/c/Users/risha/Desktop/retail-prize-optimization-MLOps/src/data_cleaning.py", line 48, in handle_data
    return self.strategy.handle_data(self.data)
  File "/mnt/c/Users/risha/Desktop/retail-prize-optimization-MLOps/src/data_cleaning.py", line 37, in handle_data
    raise e
  File "/mnt/c/Users/risha/Desktop/retail-prize-optimization-MLOps/src/data_cleaning.py", line 31, in handle_data
    x=data.drop(["Performance Index"],axis=1)
  File "/mnt/c/Users/risha/Desktop/retail-prize-optimization-MLOps/venv/lib/python3.10/site-packages/pandas/core/frame.py", line 5581, in drop
    return super().drop(
  File "/mnt/c/Users/risha/Desktop/retail-prize-optimization-MLOps/venv/lib/python3.10/site-packages/pandas/core/generic.py", line 4788, in drop
    obj = obj._drop_axis(labels, axis, level=level, errors=errors)
  File "/mnt/c/Users/risha/Desktop/retail-prize-optimization-MLOps/venv/lib/python3.10/site-packages/pandas/core/generic.py", line 4830, in _drop_axis
    new_axis = axis.drop(labels, errors=errors)
  File "/mnt/c/Users/risha/Desktop/retail-prize-optimization-MLOps/venv/lib/python3.10/site-packages/pandas/core/indexes/base.py", line 7070, in drop
    raise KeyError(f"{labels[mask].tolist()} not found in axis")
KeyError: "['Performance Index'] not found in axis"

