[2024-10-20 12:37:57 UTC] Step clean_df has started.

[2024-10-20 12:37:57 UTC] Error in data divison:No axis named 1 for object type Series

[2024-10-20 12:37:57 UTC] Error in handling data:No axis named 1 for object type Series

[2024-10-20 12:37:57 UTC] Error in cleaning and splitting data: No axis named 1 for object type Series

[2024-10-20 12:37:57 UTC] Failed to run step clean_df after 1 retries. Exiting.

[2024-10-20 12:37:57 UTC] No axis named 1 for object type Series
Traceback (most recent call last):
  File "/mnt/c/Users/risha/Desktop/retail-prize-optimization-MLOps/venv/lib/python3.10/site-packages/pandas/core/generic.py", line 576, in _get_axis_number
    return cls._AXIS_TO_AXIS_NUMBER[axis]
KeyError: 1

During handling of the above exception, another exception occurred:

Traceback (most recent call last):
  File "/mnt/c/Users/risha/Desktop/retail-prize-optimization-MLOps/venv/lib/python3.10/site-packages/zenml/orchestrators/step_launcher.py", line 292, in launch
    self._run_step(
  File "/mnt/c/Users/risha/Desktop/retail-prize-optimization-MLOps/venv/lib/python3.10/site-packages/zenml/orchestrators/step_launcher.py", line 499, in _run_step
    self._run_step_without_step_operator(
  File "/mnt/c/Users/risha/Desktop/retail-prize-optimization-MLOps/venv/lib/python3.10/site-packages/zenml/orchestrators/step_launcher.py", line 583, in _run_step_without_step_operator
    runner.run(
  File "/mnt/c/Users/risha/Desktop/retail-prize-optimization-MLOps/venv/lib/python3.10/site-packages/zenml/orchestrators/step_runner.py", line 198, in run
    return_values = step_instance.call_entrypoint(
  File "/mnt/c/Users/risha/Desktop/retail-prize-optimization-MLOps/venv/lib/python3.10/site-packages/zenml/steps/base_step.py", line 692, in call_entrypoint
    return self.entrypoint(**validated_args)
  File "/mnt/c/Users/risha/Desktop/retail-prize-optimization-MLOps/steps/clean_data.py", line 34, in clean_df
    raise e
  File "/mnt/c/Users/risha/Desktop/retail-prize-optimization-MLOps/steps/clean_data.py", line 25, in clean_df
    X_train, X_test, y_train, y_test = data_cleaning.handle_data()
  File "/mnt/c/Users/risha/Desktop/retail-prize-optimization-MLOps/src/data_cleaning.py", line 48, in handle_data
    raise e
  File "/mnt/c/Users/risha/Desktop/retail-prize-optimization-MLOps/src/data_cleaning.py", line 45, in handle_data
    return self.strategy.handle_data(self.data)
  File "/mnt/c/Users/risha/Desktop/retail-prize-optimization-MLOps/src/data_cleaning.py", line 34, in handle_data
    raise e
  File "/mnt/c/Users/risha/Desktop/retail-prize-optimization-MLOps/src/data_cleaning.py", line 28, in handle_data
    x=data.drop(["Performance Index"],axis=1)
  File "/mnt/c/Users/risha/Desktop/retail-prize-optimization-MLOps/venv/lib/python3.10/site-packages/pandas/core/series.py", line 5356, in drop
    return super().drop(
  File "/mnt/c/Users/risha/Desktop/retail-prize-optimization-MLOps/venv/lib/python3.10/site-packages/pandas/core/generic.py", line 4773, in drop
    axis_name = self._get_axis_name(axis)
  File "/mnt/c/Users/risha/Desktop/retail-prize-optimization-MLOps/venv/lib/python3.10/site-packages/pandas/core/generic.py", line 583, in _get_axis_name
    axis_number = cls._get_axis_number(axis)
  File "/mnt/c/Users/risha/Desktop/retail-prize-optimization-MLOps/venv/lib/python3.10/site-packages/pandas/core/generic.py", line 578, in _get_axis_number
    raise ValueError(f"No axis named {axis} for object type {cls.__name__}")
ValueError: No axis named 1 for object type Series

